[2021-05-08 15:33:52,636] {taskinstance.py:877} INFO - Dependencies all met for <TaskInstance: dag_4.move_files 2021-05-07T00:00:00+00:00 [queued]>
[2021-05-08 15:33:52,667] {taskinstance.py:877} INFO - Dependencies all met for <TaskInstance: dag_4.move_files 2021-05-07T00:00:00+00:00 [queued]>
[2021-05-08 15:33:52,668] {taskinstance.py:1068} INFO - 
--------------------------------------------------------------------------------
[2021-05-08 15:33:52,668] {taskinstance.py:1069} INFO - Starting attempt 1 of 3
[2021-05-08 15:33:52,669] {taskinstance.py:1070} INFO - 
--------------------------------------------------------------------------------
[2021-05-08 15:33:52,834] {taskinstance.py:1089} INFO - Executing <Task(PythonOperator): move_files> on 2021-05-07T00:00:00+00:00
[2021-05-08 15:33:52,838] {standard_task_runner.py:52} INFO - Started process 165394 to run task
[2021-05-08 15:33:52,870] {standard_task_runner.py:76} INFO - Running: ['airflow', 'tasks', 'run', 'dag_4', 'move_files', '2021-05-07T00:00:00+00:00', '--job-id', '54', '--pool', 'default_pool', '--raw', '--subdir', '/home/navneetsajwan/airflow/dags/dag__4.py', '--cfg-path', '/tmp/tmpkskfsb1_', '--error-file', '/tmp/tmp_9_23ag5']
[2021-05-08 15:33:52,871] {standard_task_runner.py:77} INFO - Job 54: Subtask move_files
[2021-05-08 15:33:53,148] {logging_mixin.py:104} INFO - Running <TaskInstance: dag_4.move_files 2021-05-07T00:00:00+00:00 [running]> on host navneetsajwan-Lenovo-G50-80
[2021-05-08 15:33:53,283] {taskinstance.py:1281} INFO - Exporting the following env vars:
AIRFLOW_CTX_DAG_EMAIL=navneet@metaorigins.com
AIRFLOW_CTX_DAG_OWNER=airflow
AIRFLOW_CTX_DAG_ID=dag_4
AIRFLOW_CTX_TASK_ID=move_files
AIRFLOW_CTX_EXECUTION_DATE=2021-05-07T00:00:00+00:00
AIRFLOW_CTX_DAG_RUN_ID=scheduled__2021-05-07T00:00:00+00:00
[2021-05-08 15:33:53,285] {taskinstance.py:1482} ERROR - Task failed with exception
Traceback (most recent call last):
  File "/home/navneetsajwan/miniconda3/lib/python3.8/shutil.py", line 788, in move
    os.rename(src, real_dst)
FileNotFoundError: [Errno 2] No such file or directory: 'usercreditaccount-20210508T113018.csv' -> '/home/navneetsajwan/airflow/singer_data/Data-2021-05-08/usercreditaccount-20210508T113018.csv'

During handling of the above exception, another exception occurred:

Traceback (most recent call last):
  File "/home/navneetsajwan/airflow/etl/lib/python3.8/site-packages/airflow/models/taskinstance.py", line 1138, in _run_raw_task
    self._prepare_and_execute_task_with_callbacks(context, task)
  File "/home/navneetsajwan/airflow/etl/lib/python3.8/site-packages/airflow/models/taskinstance.py", line 1311, in _prepare_and_execute_task_with_callbacks
    result = self._execute_task(context, task_copy)
  File "/home/navneetsajwan/airflow/etl/lib/python3.8/site-packages/airflow/models/taskinstance.py", line 1341, in _execute_task
    result = task_copy.execute(context=context)
  File "/home/navneetsajwan/airflow/etl/lib/python3.8/site-packages/airflow/operators/python.py", line 117, in execute
    return_value = self.execute_callable()
  File "/home/navneetsajwan/airflow/etl/lib/python3.8/site-packages/airflow/operators/python.py", line 128, in execute_callable
    return self.python_callable(*self.op_args, **self.op_kwargs)
  File "/home/navneetsajwan/airflow/dags/dag__4.py", line 61, in move_files
    [shutil.move(files,directory+'/'+files)for files in Transfer_data]
  File "/home/navneetsajwan/airflow/dags/dag__4.py", line 61, in <listcomp>
    [shutil.move(files,directory+'/'+files)for files in Transfer_data]
  File "/home/navneetsajwan/miniconda3/lib/python3.8/shutil.py", line 802, in move
    copy_function(src, real_dst)
  File "/home/navneetsajwan/miniconda3/lib/python3.8/shutil.py", line 432, in copy2
    copyfile(src, dst, follow_symlinks=follow_symlinks)
  File "/home/navneetsajwan/miniconda3/lib/python3.8/shutil.py", line 261, in copyfile
    with open(src, 'rb') as fsrc, open(dst, 'wb') as fdst:
FileNotFoundError: [Errno 2] No such file or directory: '/home/navneetsajwan/airflow/singer_data/Data-2021-05-08/usercreditaccount-20210508T113018.csv'
[2021-05-08 15:33:53,302] {taskinstance.py:1525} INFO - Marking task as UP_FOR_RETRY. dag_id=dag_4, task_id=move_files, execution_date=20210507T000000, start_date=20210508T100352, end_date=20210508T100353
[2021-05-08 15:33:53,324] {configuration.py:352} WARNING - section/key [smtp/smtp_user] not found in config
[2021-05-08 15:33:53,324] {email.py:184} INFO - Email alerting: attempt 1
[2021-05-08 15:33:53,326] {configuration.py:352} WARNING - section/key [smtp/smtp_user] not found in config
[2021-05-08 15:33:53,326] {email.py:184} INFO - Email alerting: attempt 1
[2021-05-08 15:33:53,327] {taskinstance.py:1538} ERROR - Failed to send email to: ['navneet@metaorigins.com']
[2021-05-08 15:33:53,327] {taskinstance.py:1539} ERROR - [Errno 111] Connection refused
Traceback (most recent call last):
  File "/home/navneetsajwan/miniconda3/lib/python3.8/shutil.py", line 788, in move
    os.rename(src, real_dst)
FileNotFoundError: [Errno 2] No such file or directory: 'usercreditaccount-20210508T113018.csv' -> '/home/navneetsajwan/airflow/singer_data/Data-2021-05-08/usercreditaccount-20210508T113018.csv'

During handling of the above exception, another exception occurred:

Traceback (most recent call last):
  File "/home/navneetsajwan/airflow/etl/lib/python3.8/site-packages/airflow/models/taskinstance.py", line 1138, in _run_raw_task
    self._prepare_and_execute_task_with_callbacks(context, task)
  File "/home/navneetsajwan/airflow/etl/lib/python3.8/site-packages/airflow/models/taskinstance.py", line 1311, in _prepare_and_execute_task_with_callbacks
    result = self._execute_task(context, task_copy)
  File "/home/navneetsajwan/airflow/etl/lib/python3.8/site-packages/airflow/models/taskinstance.py", line 1341, in _execute_task
    result = task_copy.execute(context=context)
  File "/home/navneetsajwan/airflow/etl/lib/python3.8/site-packages/airflow/operators/python.py", line 117, in execute
    return_value = self.execute_callable()
  File "/home/navneetsajwan/airflow/etl/lib/python3.8/site-packages/airflow/operators/python.py", line 128, in execute_callable
    return self.python_callable(*self.op_args, **self.op_kwargs)
  File "/home/navneetsajwan/airflow/dags/dag__4.py", line 61, in move_files
    [shutil.move(files,directory+'/'+files)for files in Transfer_data]
  File "/home/navneetsajwan/airflow/dags/dag__4.py", line 61, in <listcomp>
    [shutil.move(files,directory+'/'+files)for files in Transfer_data]
  File "/home/navneetsajwan/miniconda3/lib/python3.8/shutil.py", line 802, in move
    copy_function(src, real_dst)
  File "/home/navneetsajwan/miniconda3/lib/python3.8/shutil.py", line 432, in copy2
    copyfile(src, dst, follow_symlinks=follow_symlinks)
  File "/home/navneetsajwan/miniconda3/lib/python3.8/shutil.py", line 261, in copyfile
    with open(src, 'rb') as fsrc, open(dst, 'wb') as fdst:
FileNotFoundError: [Errno 2] No such file or directory: '/home/navneetsajwan/airflow/singer_data/Data-2021-05-08/usercreditaccount-20210508T113018.csv'

During handling of the above exception, another exception occurred:

Traceback (most recent call last):
  File "/home/navneetsajwan/airflow/etl/lib/python3.8/site-packages/airflow/models/taskinstance.py", line 1881, in email_alert
    send_email(self.task.email, subject, html_content)
  File "/home/navneetsajwan/airflow/etl/lib/python3.8/site-packages/airflow/utils/email.py", line 52, in send_email
    return backend(
  File "/home/navneetsajwan/airflow/etl/lib/python3.8/site-packages/airflow/utils/email.py", line 97, in send_email_smtp
    send_mime_email(e_from=smtp_mail_from, e_to=recipients, mime_msg=msg, dryrun=dryrun)
  File "/home/navneetsajwan/airflow/etl/lib/python3.8/site-packages/airflow/utils/email.py", line 186, in send_mime_email
    conn = _get_smtp_connection(smtp_host, smtp_port, smtp_timeout, smtp_ssl)
  File "/home/navneetsajwan/airflow/etl/lib/python3.8/site-packages/airflow/utils/email.py", line 220, in _get_smtp_connection
    else smtplib.SMTP(host=host, port=port, timeout=timeout)
  File "/home/navneetsajwan/miniconda3/lib/python3.8/smtplib.py", line 253, in __init__
    (code, msg) = self.connect(host, port)
  File "/home/navneetsajwan/miniconda3/lib/python3.8/smtplib.py", line 339, in connect
    self.sock = self._get_socket(host, port, self.timeout)
  File "/home/navneetsajwan/miniconda3/lib/python3.8/smtplib.py", line 308, in _get_socket
    return socket.create_connection((host, port), timeout,
  File "/home/navneetsajwan/miniconda3/lib/python3.8/socket.py", line 808, in create_connection
    raise err
  File "/home/navneetsajwan/miniconda3/lib/python3.8/socket.py", line 796, in create_connection
    sock.connect(sa)
ConnectionRefusedError: [Errno 111] Connection refused

During handling of the above exception, another exception occurred:

Traceback (most recent call last):
  File "/home/navneetsajwan/airflow/etl/lib/python3.8/site-packages/airflow/models/taskinstance.py", line 1536, in handle_failure
    self.email_alert(error)
  File "/home/navneetsajwan/airflow/etl/lib/python3.8/site-packages/airflow/models/taskinstance.py", line 1883, in email_alert
    send_email(self.task.email, subject, html_content_err)
  File "/home/navneetsajwan/airflow/etl/lib/python3.8/site-packages/airflow/utils/email.py", line 52, in send_email
    return backend(
  File "/home/navneetsajwan/airflow/etl/lib/python3.8/site-packages/airflow/utils/email.py", line 97, in send_email_smtp
    send_mime_email(e_from=smtp_mail_from, e_to=recipients, mime_msg=msg, dryrun=dryrun)
  File "/home/navneetsajwan/airflow/etl/lib/python3.8/site-packages/airflow/utils/email.py", line 186, in send_mime_email
    conn = _get_smtp_connection(smtp_host, smtp_port, smtp_timeout, smtp_ssl)
  File "/home/navneetsajwan/airflow/etl/lib/python3.8/site-packages/airflow/utils/email.py", line 220, in _get_smtp_connection
    else smtplib.SMTP(host=host, port=port, timeout=timeout)
  File "/home/navneetsajwan/miniconda3/lib/python3.8/smtplib.py", line 253, in __init__
    (code, msg) = self.connect(host, port)
  File "/home/navneetsajwan/miniconda3/lib/python3.8/smtplib.py", line 339, in connect
    self.sock = self._get_socket(host, port, self.timeout)
  File "/home/navneetsajwan/miniconda3/lib/python3.8/smtplib.py", line 308, in _get_socket
    return socket.create_connection((host, port), timeout,
  File "/home/navneetsajwan/miniconda3/lib/python3.8/socket.py", line 808, in create_connection
    raise err
  File "/home/navneetsajwan/miniconda3/lib/python3.8/socket.py", line 796, in create_connection
    sock.connect(sa)
ConnectionRefusedError: [Errno 111] Connection refused
[2021-05-08 15:33:53,508] {local_task_job.py:146} INFO - Task exited with return code 1
